Workbook

Sheet Read me
A1: MAT Atom Deweloper Wrocław — riders, races and results 2026
A2: Compiled 30 Sep 2026 from public sources. Every result row carries its source link (Results sheet, column J).
A4: Sheets
A5: Summary – team totals (formulas).
A6: Riders – the 20 riders on atomteam.pl (12 Continental, 8 Junior) with counts of wins, podiums, top 10s, DNFs and national titles.
A7: Events – the 50 entries of the 2026 team calendar (E01–E50) plus 16 races found in results databases that are not on the published calendar (X01–X16).
A8: Results – one row per rider per classification: stage, general classification, track event or category. This is the only sheet to edit; everything else recalculates.
A9: Matrix – best result per rider per event, coloured by place.
A11: Sources
A12: UCI races, national championships and track championships: CyclingFlash rider profiles (cyclingflash.com/profile/<rider>), which list full finishing positions including DNFs.
A13: Polish domestic races (Polish Cups, criteriums, Sowiogórski Tour, track and TTT championships): naszosie.pl race reports.
A14: Three items appear only in the team's own Instagram post (elimination races at the Youth Polish Track Championships; Polish MTB marathon championships). They are marked with the team Instagram as source.
... A25: 8. Titles and medals on the Summary sheet count Polish national championships only, each title once even when several riders share it (pairs, team time trial, team pursuit). Race-day results of the criterium final (E48) are not titles; the title is the series classification.

Sheet Summary
A1: MAT Atom Deweloper Wrocław — season 2026
A2: All figures are formulas over the Results and Events sheets.
A4: As-of date | B4: 46295 | C4: Events after this date count as Upcoming.
A6: Measure | B6: Value
A7: Result rows entered | B7: =COUNTIF(Results!$F$2:$F$482,"?*") -> 481
A8: Riders with at least one result | B8: =COUNTIF(Riders!$G$5:$G$24,">0") -> 20
A9: Wins (any classification or category) | B9: =COUNTIF(Results!$G$2:$G$482,1) -> 83
A10: Podium places (1–3) | B10: =COUNTIFS(Results!$G$2:$G$482,">=1",Results!$G$2:$G$482,"<=3") -> 180
A11: Top-10 places | B11: =COUNTIFS(Results!$G$2:$G$482,">=1",Results!$G$2:$G$482,"<=10") -> 251
A12: DNF | B12: =COUNTIF(Results!$H$2:$H$482,"DNF") -> 29
A13: Polish national titles (distinct; team and pairs titles counted once) | B13: =SUM(Results!$O$2:$O$482) -> 30
A14: Polish national championship medals (distinct) | B14: =SUM(Results!$P$2:$P$482) -> 58
A15: National championship golds counted per rider (a team title counts for each rider) | B15: =COUNTIFS(Results!$G$2:$G$482,1,Results!$K$2:$K$482,"Yes") -> 47
A16: Calendar events with team results | B16: =COUNTIFS(Events!$I$2:$I$67,"Yes",Events!$L$2:$L$67,">0") -> 37
A17: Calendar events upcoming | B17: =COUNTIF(Events!$P$2:$P$67,"Upcoming") -> 2
A18: Calendar races with no team result found | B18: =COUNTIF(Events!$P$2:$P$67,"No team result found") -> 8
A19: Extra races not on the published calendar | B19: =COUNTIFS(Events!$I$2:$I$67,"No",Events!$L$2:$L$67,">0") -> 16

Sheet Riders
A1: Riders 2026
A2: Counts come from the Results sheet. Positions count across every classification and category entered.
A4: Rider | B4: Nat. | C4: Squad | D4: Category | E4: Instagram | F4: Results profile | G4: Result rows | H4: Events with results | I4: Wins | J4: Podiums (1–3) | K4: Top 10 | L4: DNF | M4: National championship golds | N4: Notes
A5: Olga Wankiewicz | B5: POL | C5: Continental | D5: Elite | E5: @olga_wankiewicz | F5: https://cyclingflash.com/profile/olga-wankiewicz | G5: =COUNTIF(Results!$F$2:$F$482,A5) -> 30 | H5: =SUMIFS(Results!$M$2:$M$482,Results!$F$2:$F$482,A5) -> 17 | I5: =COUNTIFS(Results!$F$2:$F$482,A5,Results!$G$2:$G$482,1) -> 1 | J5: =COUNTIFS(Results!$F$2:$F$482,A5,Results!$G$2:$G$482,">=1",Results!$G$2:$G$482,"<=3") -> 5 | K5: =COUNTIFS(Results!$F$2:$F$482,A5,Results!$G$2:$G$482,">=1",Results!$G$2:$G$482,"<=10") -> 17 | L5: =COUNTIFS(Results!$F$2:$F$482,A5,Results!$H$2:$H$482,"DNF") -> 0 | M5: =COUNTIFS(Results!$F$2:$F$482,A5,Results!$G$2:$G$482,1,Results!$K$2:$K$482,"Yes") -> 1
A6: Tamara Szalińska | B6: POL | C6: Continental | D6: Elite | E6: @tamara_szalinska | F6: https://cyclingflash.com/profile/tamara-szalinska | G6: =COUNTIF(Results!$F$2:$F$482,A6) -> 20 | H6: =SUMIFS(Results!$M$2:$M$482,Results!$F$2:$F$482,A6) -> 12 | I6: =COUNTIFS(Results!$F$2:$F$482,A6,Results!$G$2:$G$482,1) -> 1 | J6: =COUNTIFS(Results!$F$2:$F$482,A6,Results!$G$2:$G$482,">=1",Results!$G$2:$G$482,"<=3") -> 4 | K6: =COUNTIFS(Results!$F$2:$F$482,A6,Results!$G$2:$G$482,">=1",Results!$G$2:$G$482,"<=10") -> 9 | L6: =COUNTIFS(Results!$F$2:$F$482,A6,Results!$H$2:$H$482,"DNF") -> 0 | M6: =COUNTIFS(Results!$F$2:$F$482,A6,Results!$G$2:$G$482,1,Results!$K$2:$K$482,"Yes") -> 1
A7: Maja Tracka | B7: POL | C7: Continental | D7: U23 | E7: @trackaaaa | F7: https://cyclingflash.com/profile/maja-tracka | G7: =COUNTIF(Results!$F$2:$F$482,A7) -> 38 | H7: =SUMIFS(Results!$M$2:$M$482,Results!$F$2:$F$482,A7) -> 18 | I7: =COUNTIFS(Results!$F$2:$F$482,A7,Results!$G$2:$G$482,1) -> 10 | J7: =COUNTIFS(Results!$F$2:$F$482,A7,Results!$G$2:$G$482,">=1",Results!$G$2:$G$482,"<=3") -> 15 | K7: =COUNTIFS(Results!$F$2:$F$482,A7,Results!$G$2:$G$482,">=1",Results!$G$2:$G$482,"<=10") -> 20 | L7: =COUNTIFS(Results!$F$2:$F$482,A7,Results!$H$2:$H$482,"DNF") -> 5 | M7: =COUNTIFS(Results!$F$2:$F$482,A7,Results!$G$2:$G$482,1,Results!$K$2:$K$482,"Yes") -> 7
A8: Martyna Szczęsna | B8: POL | C8: Continental | D8: U23 | E8: @szczesna.martynka | F8: https://cyclingflash.com/profile/martyna-szczesna | G8: =COUNTIF(Results!$F$2:$F$482,A8) -> 53 | H8: =SUMIFS(Results!$M$2:$M$482,Results!$F$2:$F$482,A8) -> 21 | I8: =COUNTIFS(Results!$F$2:$F$482,A8,Results!$G$2:$G$482,1) -> 18 | J8: =COUNTIFS(Results!$F$2:$F$482,A8,Results!$G$2:$G$482,">=1",Results!$G$2:$G$482,"<=3") -> 21 | K8: =COUNTIFS(Results!$F$2:$F$482,A8,Results!$G$2:$G$482,">=1",Results!$G$2:$G$482,"<=10") -> 32 | L8: =COUNTIFS(Results!$F$2:$F$482,A8,Results!$H$2:$H$482,"DNF") -> 2 | M8: =COUNTIFS(Results!$F$2:$F$482,A8,Results!$G$2:$G$482,1,Results!$K$2:$K$482,"Yes") -> 13
A9: Eliza Rabażyńska | B9: POL | C9: Continental | D9: U23 | E9: @elizaa_rabaa | F9: https://cyclingflash.com/profile/eliza-rabazynska | G9: =COUNTIF(Results!$F$2:$F$482,A9) -> 22 | H9: =SUMIFS(Results!$M$2:$M$482,Results!$F$2:$F$482,A9) -> 12 | I9: =COUNTIFS(Results!$F$2:$F$482,A9,Results!$G$2:$G$482,1) -> 2 | J9: =COUNTIFS(Results!$F$2:$F$482,A9,Results!$G$2:$G$482,">=1",Results!$G$2:$G$482,"<=3") -> 9 | K9: =COUNTIFS(Results!$F$2:$F$482,A9,Results!$G$2:$G$482,">=1",Results!$G$2:$G$482,"<=10") -> 13 | L9: =COUNTIFS(Results!$F$2:$F$482,A9,Results!$H$2:$H$482,"DNF") -> 1 | M9: =COUNTIFS(Results!$F$2:$F$482,A9,Results!$G$2:$G$482,1,Results!$K$2:$K$482,"Yes") -> 1
A10: Alicja Matuła | B10: POL | C10: Continental | D10: U23 | E10: @alqa.matula | F10: https://cyclingflash.com/profile/alicja-matula | G10: =COUNTIF(Results!$F$2:$F$482,A10) -> 34 | H10: =SUMIFS(Results!$M$2:$M$482,Results!$F$2:$F$482,A10) -> 19 | I10: =COUNTIFS(Results!$F$2:$F$482,A10,Results!$G$2:$G$482,1) -> 6 | J10: =COUNTIFS(Results!$F$2:$F$482,A10,Results!$G$2:$G$482,">=1",Results!$G$2:$G$482,"<=3") -> 17 | K10: =COUNTIFS(Results!$F$2:$F$482,A10,Results!$G$2:$G$482,">=1",Results!$G$2:$G$482,"<=10") -> 18 | L10: =COUNTIFS(Results!$F$2:$F$482,A10,Results!$H$2:$H$482,"DNF") -> 5 | M10: =COUNTIFS(Results!$F$2:$F$482,A10,Results!$G$2:$G$482,1,Results!$K$2:$K$482,"Yes") -> 3
A11: Urszula Sipko | B11: POL | C11: Continental | D11: U23 | E11: @ula_sipko | F11: https://cyclingflash.com/profile/urszula-sipko | G11: =COUNTIF(Results!$F$2:$F$482,A11) -> 35 | H11: =SUMIFS(Results!$M$2:$M$482,Results!$F$2:$F$482,A11) -> 17 | I11: =COUNTIFS(Results!$F$2:$F$482,A11,Results!$G$2:$G$482,1) -> 4 | J11: =COUNTIFS(Results!$F$2:$F$482,A11,Results!$G$2:$G$482,">=1",Results!$G$2:$G$482,"<=3") -> 11 | K11: =COUNTIFS(Results!$F$2:$F$482,A11,Results!$G$2:$G$482,">=1",Results!$G$2:$G$482,"<=10") -> 16 | L11: =COUNTIFS(Results!$F$2:$F$482,A11,Results!$H$2:$H$482,"DNF") -> 3 | M11: =COUNTIFS(Results!$F$2:$F$482,A11,Results!$G$2:$G$482,1,Results!$K$2:$K$482,"Yes") -> 2
A12: Sofia Ungerová | B12: SVK | C12: Continental | D12: U23 | E12: @s.ungerova | F12: https://cyclingflash.com/profile/sofia-ungerova | G12: =COUNTIF(Results!$F$2:$F$482,A12) -> 30 | H12: =SUMIFS(Results!$M$2:$M$482,Results!$F$2:$F$482,A12) -> 14 | I12: =COUNTIFS(Results!$F$2:$F$482,A12,Results!$G$2:$G$482,1) -> 3 | J12: =COUNTIFS(Results!$F$2:$F$482,A12,Results!$G$2:$G$482,">=1",Results!$G$2:$G$482,"<=3") -> 12 | K12: =COUNTIFS(Results!$F$2:$F$482,A12,Results!$G$2:$G$482,">=1",Results!$G$2:$G$482,"<=10") -> 19 | L12: =COUNTIFS(Results!$F$2:$F$482,A12,Results!$H$2:$H$482,"DNF") -> 1 | M12: =COUNTIFS(Results!$F$2:$F$482,A12,Results!$G$2:$G$482,1,Results!$K$2:$K$482,"Yes") -> 0
A13: Nadia Hartman | B13: POL | C13: Continental | D13: U23 | E13: @nadiaahartman | F13: https://cyclingflash.com/profile/nadia-hartman | G13: =COUNTIF(Results!$F$2:$F$482,A13) -> 32 | H13: =SUMIFS(Results!$M$2:$M$482,Results!$F$2:$F$482,A13) -> 15 | I13: =COUNTIFS(Results!$F$2:$F$482,A13,Results!$G$2:$G$482,1) -> 3 | J13: =COUNTIFS(Results!$F$2:$F$482,A13,Results!$G$2:$G$482,">=1",Results!$G$2:$G$482,"<=3") -> 9 | K13: =COUNTIFS(Results!$F$2:$F$482,A13,Results!$G$2:$G$482,">=1",Results!$G$2:$G$482,"<=10") -> 10 | L13: =COUNTIFS(Results!$F$2:$F$482,A13,Results!$H$2:$H$482,"DNF") -> 0 | M13: =COUNTIFS(Results!$F$2:$F$482,A13,Results!$G$2:$G$482,1,Results!$K$2:$K$482,"Yes") -> 2
A14: Anna Gaborska | B14: POL | C14: Continental | D14: U23 | E14: @a.gaborska | F14: https://cyclingflash.com/profile/anna-gaborska | G14: =COUNTIF(Results!$F$2:$F$482,A14) -> 22 | H14: =SUMIFS(Results!$M$2:$M$482,Results!$F$2:$F$482,A14) -> 13 | I14: =COUNTIFS(Results!$F$2:$F$482,A14,Results!$G$2:$G$482,1) -> 2 | J14: =COUNTIFS(Results!$F$2:$F$482,A14,Results!$G$2:$G$482,">=1",Results!$G$2:$G$482,"<=3") -> 6 | K14: =COUNTIFS(Results!$F$2:$F$482,A14,Results!$G$2:$G$482,">=1",Results!$G$2:$G$482,"<=10") -> 10 | L14: =COUNTIFS(Results!$F$2:$F$482,A14,Results!$H$2:$H$482,"DNF") -> 2 | M14: =COUNTIFS(Results!$F$2:$F$482,A14,Results!$G$2:$G$482,1,Results!$K$2:$K$482,"Yes") -> 2
A15: Gabriela Kaczmarczyk | B15: POL | C15: Continental | D15: U23 | E15: @g__kaczmarczyk | F15: https://cyclingflash.com/profile/gabriela-kaczmarczyk | G15: =COUNTIF(Results!$F$2:$F$482,A15) -> 18 | H15: =SUMIFS(Results!$M$2:$M$482,Results!$F$2:$F$482,A15) -> 13 | I15: =COUNTIFS(Results!$F$2:$F$482,A15,Results!$G$2:$G$482,1) -> 4 | J15: =COUNTIFS(Results!$F$2:$F$482,A15,Results!$G$2:$G$482,">=1",Results!$G$2:$G$482,"<=3") -> 9 | K15: =COUNTIFS(Results!$F$2:$F$482,A15,Results!$G$2:$G$482,">=1",Results!$G$2:$G$482,"<=10") -> 12 | L15: =COUNTIFS(Results!$F$2:$F$482,A15,Results!$H$2:$H$482,"DNF") -> 3 | M15: =COUNTIFS(Results!$F$2:$F$482,A15,Results!$G$2:$G$482,1,Results!$K$2:$K$482,"Yes") -> 3
A16: Daria Dębicka | B16: POL | C16: Continental | D16: U23 | E16: @__debicka__ | F16: https://cyclingflash.com/profile/daria-debicka | G16: =COUNTIF(Results!$F$2:$F$482,A16) -> 9 | H16: =SUMIFS(Results!$M$2:$M$482,Results!$F$2:$F$482,A16) -> 7 | I16: =COUNTIFS(Results!$F$2:$F$482,A16,Results!$G$2:$G$482,1) -> 1 | J16: =COUNTIFS(Results!$F$2:$F$482,A16,Results!$G$2:$G$482,">=1",Results!$G$2:$G$482,"<=3") -> 4 | K16: =COUNTIFS(Results!$F$2:$F$482,A16,Results!$G$2:$G$482,">=1",Results!$G$2:$G$482,"<=10") -> 4 | L16: =COUNTIFS(Results!$F$2:$F$482,A16,Results!$H$2:$H$482,"DNF") -> 1 | M16: =COUNTIFS(Results!$F$2:$F$482,A16,Results!$G$2:$G$482,1,Results!$K$2:$K$482,"Yes") -> 0
... A24: Natalia Gacek | B24: POL | C24: Junior | D24: U19 | E24: @_na4alia_ | F24: https://cyclingflash.com/profile/natalia-gacek | G24: =COUNTIF(Results!$F$2:$F$482,A24) -> 7 | H24: =SUMIFS(Results!$M$2:$M$482,Results!$F$2:$F$482,A24) -> 4 | I24: =COUNTIFS(Results!$F$2:$F$482,A24,Results!$G$2:$G$482,1) -> 0 | J24: =COUNTIFS(Results!$F$2:$F$482,A24,Results!$G$2:$G$482,">=1",Results!$G$2:$G$482,"<=3") -> 0 | K24: =COUNTIFS(Results!$F$2:$F$482,A24,Results!$G$2:$G$482,">=1",Results!$G$2:$G$482,"<=10") -> 0 | L24: =COUNTIFS(Results!$F$2:$F$482,A24,Results!$H$2:$H$482,"DNF") -> 3 | M24: =COUNTIFS(Results!$F$2:$F$482,A24,Results!$G$2:$G$482,1,Results!$K$2:$K$482,"Yes") -> 0
A25: Team total | G25: =SUM(G5:G24) -> 481 | H25: =SUM(H5:H24) -> 251 | I25: =SUM(I5:I24) -> 83 | J25: =SUM(J5:J24) -> 180 | K25: =SUM(K5:K24) -> 251 | L25: =SUM(L5:L24) -> 29 | M25: =SUM(M5:M24) -> 47

Sheet Events
A1: Event ID | B1: Start | C1: End | D1: Event | E1: Location | F1: Country | G1: Discipline | H1: Class | I1: On team calendar | J1: National championship | K1: Training | L1: Result rows | M1: Riders with results | N1: Best result | O1: Wins | P1: Status | Q1: Notes
A2: E01 | B2: 46026 | C2: 46026 | D2: 4th Cyclocross im. Z. Hanusika | E2: Tychy | F2: POL | G2: CX | I2: Yes | J2: No | K2: No | L2: =COUNTIF(Results!$A$2:$A$482,A2) -> 1 | M2: =SUMIFS(Results!$M$2:$M$482,Results!$A$2:$A$482,A2) -> 1 | N2: =IF(COUNTIFS(Results!$A$2:$A$482,A2,Results!$G$2:$G$482,">0")=0,"",_xlfn.MINIFS(Results!$G$2:$G$482,Results!$A$2:$A$482,A2,Results!$G$2:$G$482,">0")) -> 2 | O2: =COUNTIFS(Results!$A$2:$A$482,A2,Results!$G$2:$G$482,1) -> 0 | P2: =IF(K2="Yes","Training",IF(L2>0,"Results found",IF(AND(B2<>"",B2>Summary!$B$4),"Upcoming","No team result found"))) -> Results found | Q2: Team site text read '44th'; naszosie reports the IV (4th) edition on 4 Jan.
A3: E02 | B3: 46031 | C3: 46033 | D3: Przełajowe Mistrzostwa Polski (Polish CX Championships) | E3: Ełk | F3: POL | G3: CX | H3: NCh. | I3: Yes | J3: Yes | K3: No | L3: =COUNTIF(Results!$A$2:$A$482,A3) -> 8 | M3: =SUMIFS(Results!$M$2:$M$482,Results!$A$2:$A$482,A3) -> 5 | N3: =IF(COUNTIFS(Results!$A$2:$A$482,A3,Results!$G$2:$G$482,">0")=0,"",_xlfn.MINIFS(Results!$G$2:$G$482,Results!$A$2:$A$482,A3,Results!$G$2:$G$482,">0")) -> 1 | O3: =COUNTIFS(Results!$A$2:$A$482,A3,Results!$G$2:$G$482,1) -> 1 | P3: =IF(K3="Yes","Training",IF(L3>0,"Results found",IF(AND(B3<>"",B3>Summary!$B$4),"Upcoming","No team result found"))) -> Results found
A4: E03 | B4: 46054 | C4: 46058 | D4: UEC Track Elite European Championships | E4: Konya | F4: TUR | G4: TRACK | H4: ECh. | I4: Yes | J4: No | K4: No | L4: =COUNTIF(Results!$A$2:$A$482,A4) -> 9 | M4: =SUMIFS(Results!$M$2:$M$482,Results!$A$2:$A$482,A4) -> 4 | N4: =IF(COUNTIFS(Results!$A$2:$A$482,A4,Results!$G$2:$G$482,">0")=0,"",_xlfn.MINIFS(Results!$G$2:$G$482,Results!$A$2:$A$482,A4,Results!$G$2:$G$482,">0")) -> 5 | O4: =COUNTIFS(Results!$A$2:$A$482,A4,Results!$G$2:$G$482,1) -> 0 | P4: =IF(K4="Yes","Training",IF(L4>0,"Results found",IF(AND(B4<>"",B4>Summary!$B$4),"Upcoming","No team result found"))) -> Results found | Q4: Riders raced for Poland.
A5: E04 | B5: 46056 | C5: 46056 | D5: Training consultation | E5: Pruszków | F5: POL | G5: TRACK | I5: Yes | J5: No | K5: Yes | L5: =COUNTIF(Results!$A$2:$A$482,A5) -> 0 | M5: =SUMIFS(Results!$M$2:$M$482,Results!$A$2:$A$482,A5) -> 0 | N5: =IF(COUNTIFS(Results!$A$2:$A$482,A5,Results!$G$2:$G$482,">0")=0,"",_xlfn.MINIFS(Results!$G$2:$G$482,Results!$A$2:$A$482,A5,Results!$G$2:$G$482,">0")) | O5: =COUNTIFS(Results!$A$2:$A$482,A5,Results!$G$2:$G$482,1) -> 0 | P5: =IF(K5="Yes","Training",IF(L5>0,"Results found",IF(AND(B5<>"",B5>Summary!$B$4),"Upcoming","No team result found"))) -> Training
A6: E05 | B6: 46060 | C6: 46075 | D6: Training camp | F6: CRO | G6: ROAD | I6: Yes | J6: No | K6: Yes | L6: =COUNTIF(Results!$A$2:$A$482,A6) -> 0 | M6: =SUMIFS(Results!$M$2:$M$482,Results!$A$2:$A$482,A6) -> 0 | N6: =IF(COUNTIFS(Results!$A$2:$A$482,A6,Results!$G$2:$G$482,">0")=0,"",_xlfn.MINIFS(Results!$G$2:$G$482,Results!$A$2:$A$482,A6,Results!$G$2:$G$482,">0")) | O6: =COUNTIFS(Results!$A$2:$A$482,A6,Results!$G$2:$G$482,1) -> 0 | P6: =IF(K6="Yes","Training",IF(L6>0,"Results found",IF(AND(B6<>"",B6>Summary!$B$4),"Upcoming","No team result found"))) -> Training
A7: E06 | B7: 46074 | C7: 46075 | D7: Polish Cup (track) – Puchar Polski | E7: Pruszków | F7: POL | G7: TRACK | H7: Nat. | I7: Yes | J7: No | K7: No | L7: =COUNTIF(Results!$A$2:$A$482,A7) -> 7 | M7: =SUMIFS(Results!$M$2:$M$482,Results!$A$2:$A$482,A7) -> 4 | N7: =IF(COUNTIFS(Results!$A$2:$A$482,A7,Results!$G$2:$G$482,">0")=0,"",_xlfn.MINIFS(Results!$G$2:$G$482,Results!$A$2:$A$482,A7,Results!$G$2:$G$482,">0")) -> 1 | O7: =COUNTIFS(Results!$A$2:$A$482,A7,Results!$G$2:$G$482,1) -> 3 | P7: =IF(K7="Yes","Training",IF(L7>0,"Results found",IF(AND(B7<>"",B7>Summary!$B$4),"Upcoming","No team result found"))) -> Results found
A8: E07 | B8: 46085 | C8: 46085 | D8: UMAG Classic Ladies | E8: Umag | F8: CRO | G8: ROAD | H8: 1.2 | I8: Yes | J8: No | K8: No | L8: =COUNTIF(Results!$A$2:$A$482,A8) -> 6 | M8: =SUMIFS(Results!$M$2:$M$482,Results!$A$2:$A$482,A8) -> 6 | N8: =IF(COUNTIFS(Results!$A$2:$A$482,A8,Results!$G$2:$G$482,">0")=0,"",_xlfn.MINIFS(Results!$G$2:$G$482,Results!$A$2:$A$482,A8,Results!$G$2:$G$482,">0")) -> 4 | O8: =COUNTIFS(Results!$A$2:$A$482,A8,Results!$G$2:$G$482,1) -> 0 | P8: =IF(K8="Yes","Training",IF(L8>0,"Results found",IF(AND(B8<>"",B8>Summary!$B$4),"Upcoming","No team result found"))) -> Results found
A9: E08 | B9: 46088 | C9: 46100 | D9: Training camp | F9: CRO | G9: ROAD | I9: Yes | J9: No | K9: Yes | L9: =COUNTIF(Results!$A$2:$A$482,A9) -> 0 | M9: =SUMIFS(Results!$M$2:$M$482,Results!$A$2:$A$482,A9) -> 0 | N9: =IF(COUNTIFS(Results!$A$2:$A$482,A9,Results!$G$2:$G$482,">0")=0,"",_xlfn.MINIFS(Results!$G$2:$G$482,Results!$A$2:$A$482,A9,Results!$G$2:$G$482,">0")) | O9: =COUNTIFS(Results!$A$2:$A$482,A9,Results!$G$2:$G$482,1) -> 0 | P9: =IF(K9="Yes","Training",IF(L9>0,"Results found",IF(AND(B9<>"",B9>Summary!$B$4),"Upcoming","No team result found"))) -> Training
A10: E09 | B10: 46089 | C10: 46089 | D10: POREČ Classic Ladies | E10: Poreč | F10: CRO | G10: ROAD | H10: 1.2 | I10: Yes | J10: No | K10: No | L10: =COUNTIF(Results!$A$2:$A$482,A10) -> 6 | M10: =SUMIFS(Results!$M$2:$M$482,Results!$A$2:$A$482,A10) -> 6 | N10: =IF(COUNTIFS(Results!$A$2:$A$482,A10,Results!$G$2:$G$482,">0")=0,"",_xlfn.MINIFS(Results!$G$2:$G$482,Results!$A$2:$A$482,A10,Results!$G$2:$G$482,">0")) -> 2 | O10: =COUNTIFS(Results!$A$2:$A$482,A10,Results!$G$2:$G$482,1) -> 0 | P10: =IF(K10="Yes","Training",IF(L10>0,"Results found",IF(AND(B10<>"",B10>Summary!$B$4),"Upcoming","No team result found"))) -> Results found
A11: E10 | B11: 46103 | C11: 46103 | D11: Midwest Cycling Classic | F11: BEL | G11: ROAD | H11: 1.1 | I11: Yes | J11: No | K11: No | L11: =COUNTIF(Results!$A$2:$A$482,A11) -> 7 | M11: =SUMIFS(Results!$M$2:$M$482,Results!$A$2:$A$482,A11) -> 7 | N11: =IF(COUNTIFS(Results!$A$2:$A$482,A11,Results!$G$2:$G$482,">0")=0,"",_xlfn.MINIFS(Results!$G$2:$G$482,Results!$A$2:$A$482,A11,Results!$G$2:$G$482,">0")) -> 9 | O11: =COUNTIFS(Results!$A$2:$A$482,A11,Results!$G$2:$G$482,1) -> 0 | P11: =IF(K11="Yes","Training",IF(L11>0,"Results found",IF(AND(B11<>"",B11>Summary!$B$4),"Upcoming","No team result found"))) -> Results found
A12: E11 | B12: 46109 | C12: 46109 | D12: Trofeo Cinelli – VC Hlohovec | E12: Hlohovec | F12: CZE | G12: ROAD | I12: Yes | J12: No | K12: No | L12: =COUNTIF(Results!$A$2:$A$482,A12) -> 0 | M12: =SUMIFS(Results!$M$2:$M$482,Results!$A$2:$A$482,A12) -> 0 | N12: =IF(COUNTIFS(Results!$A$2:$A$482,A12,Results!$G$2:$G$482,">0")=0,"",_xlfn.MINIFS(Results!$G$2:$G$482,Results!$A$2:$A$482,A12,Results!$G$2:$G$482,">0")) | O12: =COUNTIFS(Results!$A$2:$A$482,A12,Results!$G$2:$G$482,1) -> 0 | P12: =IF(K12="Yes","Training",IF(L12>0,"Results found",IF(AND(B12<>"",B12>Summary!$B$4),"Upcoming","No team result found"))) -> No team result found
A13: E12 | B13: 46116 | C13: 46116 | D13: NXT Classic | F13: NED | G13: ROAD | H13: 1.2 | I13: Yes | J13: No | K13: No | L13: =COUNTIF(Results!$A$2:$A$482,A13) -> 6 | M13: =SUMIFS(Results!$M$2:$M$482,Results!$A$2:$A$482,A13) -> 6 | N13: =IF(COUNTIFS(Results!$A$2:$A$482,A13,Results!$G$2:$G$482,">0")=0,"",_xlfn.MINIFS(Results!$G$2:$G$482,Results!$A$2:$A$482,A13,Results!$G$2:$G$482,">0")) -> 21 | O13: =COUNTIFS(Results!$A$2:$A$482,A13,Results!$G$2:$G$482,1) -> 0 | P13: =IF(K13="Yes","Training",IF(L13>0,"Results found",IF(AND(B13<>"",B13>Summary!$B$4),"Upcoming","No team result found"))) -> Results found | Q13: Team site lists 1.1; CyclingFlash and naszosie list 1.2.
A14: E13 | B14: 46118 | C14: 46118 | D14: Ronde de Mouscron | E14: Mouscron | F14: BEL | G14: ROAD | H14: 1.1 | I14: Yes | J14: No | K14: No | L14: =COUNTIF(Results!$A$2:$A$482,A14) -> 7 | M14: =SUMIFS(Results!$M$2:$M$482,Results!$A$2:$A$482,A14) -> 7 | N14: =IF(COUNTIFS(Results!$A$2:$A$482,A14,Results!$G$2:$G$482,">0")=0,"",_xlfn.MINIFS(Results!$G$2:$G$482,Results!$A$2:$A$482,A14,Results!$G$2:$G$482,">0")) -> 7 | O14: =COUNTIFS(Results!$A$2:$A$482,A14,Results!$G$2:$G$482,1) -> 0 | P14: =IF(K14="Yes","Training",IF(L14>0,"Results found",IF(AND(B14<>"",B14>Summary!$B$4),"Upcoming","No team result found"))) -> Results found
A15: E14 | B15: 46120 | C15: 46120 | D15: Scheldeprijs Vrouwen Elite | F15: BEL | G15: ROAD | H15: 1.Pro | I15: Yes | J15: No | K15: No | L15: =COUNTIF(Results!$A$2:$A$482,A15) -> 6 | M15: =SUMIFS(Results!$M$2:$M$482,Results!$A$2:$A$482,A15) -> 6 | N15: =IF(COUNTIFS(Results!$A$2:$A$482,A15,Results!$G$2:$G$482,">0")=0,"",_xlfn.MINIFS(Results!$G$2:$G$482,Results!$A$2:$A$482,A15,Results!$G$2:$G$482,">0")) -> 61 | O15: =COUNTIFS(Results!$A$2:$A$482,A15,Results!$G$2:$G$482,1) -> 0 | P15: =IF(K15="Yes","Training",IF(L15>0,"Results found",IF(AND(B15<>"",B15>Summary!$B$4),"Upcoming","No team result found"))) -> Results found
A16: E15 | B16: 46124 | C16: 46124 | D16: Ślężański Mnich | F16: POL | G16: ROAD | H16: Nat. | I16: Yes | J16: No | K16: No | L16: =COUNTIF(Results!$A$2:$A$482,A16) -> 6 | M16: =SUMIFS(Results!$M$2:$M$482,Results!$A$2:$A$482,A16) -> 4 | N16: =IF(COUNTIFS(Results!$A$2:$A$482,A16,Results!$G$2:$G$482,">0")=0,"",_xlfn.MINIFS(Results!$G$2:$G$482,Results!$A$2:$A$482,A16,Results!$G$2:$G$482,">0")) -> 1 | O16: =COUNTIFS(Results!$A$2:$A$482,A16,Results!$G$2:$G$482,1) -> 2 | P16: =IF(K16="Yes","Training",IF(L16>0,"Results found",IF(AND(B16<>"",B16>Summary!$B$4),"Upcoming","No team result found"))) -> Results found
A17: E16 | B17: 46129 | C17: 46129 | D17: De Brabantse Pijl | E17: Overijse | F17: BEL | G17: ROAD | H17: 1.Pro | I17: Yes | J17: No | K17: No | L17: =COUNTIF(Results!$A$2:$A$482,A17) -> 6 | M17: =SUMIFS(Results!$M$2:$M$482,Results!$A$2:$A$482,A17) -> 6 | N17: =IF(COUNTIFS(Results!$A$2:$A$482,A17,Results!$G$2:$G$482,">0")=0,"",_xlfn.MINIFS(Results!$G$2:$G$482,Results!$A$2:$A$482,A17,Results!$G$2:$G$482,">0")) -> 15 | O17: =COUNTIFS(Results!$A$2:$A$482,A17,Results!$G$2:$G$482,1) -> 0 | P17: =IF(K17="Yes","Training",IF(L17>0,"Results found",IF(AND(B17<>"",B17>Summary!$B$4),"Upcoming","No team result found"))) -> Results found
A18: E17 | B18: 46130 | C18: 46131 | D18: Polish Cup (road) | E18: Lubartów | F18: POL | G18: ROAD | H18: Nat. | I18: Yes | J18: No | K18: No | L18: =COUNTIF(Results!$A$2:$A$482,A18) -> 0 | M18: =SUMIFS(Results!$M$2:$M$482,Results!$A$2:$A$482,A18) -> 0 | N18: =IF(COUNTIFS(Results!$A$2:$A$482,A18,Results!$G$2:$G$482,">0")=0,"",_xlfn.MINIFS(Results!$G$2:$G$482,Results!$A$2:$A$482,A18,Results!$G$2:$G$482,">0")) | O18: =COUNTIFS(Results!$A$2:$A$482,A18,Results!$G$2:$G$482,1) -> 0 | P18: =IF(K18="Yes","Training",IF(L18>0,"Results found",IF(AND(B18<>"",B18>Summary!$B$4),"Upcoming","No team result found"))) -> No team result found
A19: E18 | B19: 46136 | C19: 46138 | D19: EPZ Omloop van Borsele | E19: 's-Heerenhoek | F19: NED | G19: ROAD | H19: 2.Ncup | I19: Yes | J19: No | K19: No | L19: =COUNTIF(Results!$A$2:$A$482,A19) -> 16 | M19: =SUMIFS(Results!$M$2:$M$482,Results!$A$2:$A$482,A19) -> 4 | N19: =IF(COUNTIFS(Results!$A$2:$A$482,A19,Results!$G$2:$G$482,">0")=0,"",_xlfn.MINIFS(Results!$G$2:$G$482,Results!$A$2:$A$482,A19,Results!$G$2:$G$482,">0")) -> 15 | O19: =COUNTIFS(Results!$A$2:$A$482,A19,Results!$G$2:$G$482,1) -> 0 | P19: =IF(K19="Yes","Training",IF(L19>0,"Results found",IF(AND(B19<>"",B19>Summary!$B$4),"Upcoming","No team result found"))) -> Results found | Q19: Junior Nations Cup; juniors raced.
A20: E19 | B20: 46137 | C20: 46138 | D20: Polish Cup (road) | E20: Lubań / Leśna | F20: POL | G20: ROAD | H20: Nat. | I20: Yes | J20: No | K20: No | L20: =COUNTIF(Results!$A$2:$A$482,A20) -> 9 | M20: =SUMIFS(Results!$M$2:$M$482,Results!$A$2:$A$482,A20) -> 5 | N20: =IF(COUNTIFS(Results!$A$2:$A$482,A20,Results!$G$2:$G$482,">0")=0,"",_xlfn.MINIFS(Results!$G$2:$G$482,Results!$A$2:$A$482,A20,Results!$G$2:$G$482,">0")) -> 1 | O20: =COUNTIFS(Results!$A$2:$A$482,A20,Results!$G$2:$G$482,1) -> 4 | P20: =IF(K20="Yes","Training",IF(L20>0,"Results found",IF(AND(B20<>"",B20>Summary!$B$4),"Upcoming","No team result found"))) -> Results found | Q20: ITT in Lubań, road race in Leśna.
A21: E20 | B21: 46142 | C21: 46145 | D21: Gracia Orlová | E21: Orlová | F21: CZE | G21: ROAD | H21: 2.2 | I21: Yes | J21: No | K21: No | L21: =COUNTIF(Results!$A$2:$A$482,A21) -> 39 | M21: =SUMIFS(Results!$M$2:$M$482,Results!$A$2:$A$482,A21) -> 6 | N21: =IF(COUNTIFS(Results!$A$2:$A$482,A21,Results!$G$2:$G$482,">0")=0,"",_xlfn.MINIFS(Results!$G$2:$G$482,Results!$A$2:$A$482,A21,Results!$G$2:$G$482,">0")) -> 1 | O21: =COUNTIFS(Results!$A$2:$A$482,A21,Results!$G$2:$G$482,1) -> 2 | P21: =IF(K21="Yes","Training",IF(L21>0,"Results found",IF(AND(B21<>"",B21>Summary!$B$4),"Upcoming","No team result found"))) -> Results found
A22: E21 | B22: 46145 | C22: 46145 | D22: Criterium Lubawa (MP criterium qualifier) | E22: Lubawa | F22: POL | G22: ROAD | H22: Nat. | I22: Yes | J22: No | K22: No | L22: =COUNTIF(Results!$A$2:$A$482,A22) -> 1 | M22: =SUMIFS(Results!$M$2:$M$482,Results!$A$2:$A$482,A22) -> 1 | N22: =IF(COUNTIFS(Results!$A$2:$A$482,A22,Results!$G$2:$G$482,">0")=0,"",_xlfn.MINIFS(Results!$G$2:$G$482,Results!$A$2:$A$482,A22,Results!$G$2:$G$482,">0")) -> 1 | O22: =COUNTIFS(Results!$A$2:$A$482,A22,Results!$G$2:$G$482,1) -> 1 | P22: =IF(K22="Yes","Training",IF(L22>0,"Results found",IF(AND(B22<>"",B22>Summary!$B$4),"Upcoming","No team result found"))) -> Results found
A23: E22 | B23: 46151 | C23: 46152 | D23: Polish Cup (road) | E23: Zamość (reported: Suchowola) | F23: POL | G23: ROAD | H23: Nat. | I23: Yes | J23: No | K23: No | L23: =COUNTIF(Results!$A$2:$A$482,A23) -> 4 | M23: =SUMIFS(Results!$M$2:$M$482,Results!$A$2:$A$482,A23) -> 2 | N23: =IF(COUNTIFS(Results!$A$2:$A$482,A23,Results!$G$2:$G$482,">0")=0,"",_xlfn.MINIFS(Results!$G$2:$G$482,Results!$A$2:$A$482,A23,Results!$G$2:$G$482,">0")) -> 1 | O23: =COUNTIFS(Results!$A$2:$A$482,A23,Results!$G$2:$G$482,1) -> 2 | P23: =IF(K23="Yes","Training",IF(L23>0,"Results found",IF(AND(B23<>"",B23>Summary!$B$4),"Upcoming","No team result found"))) -> Results found | Q23: naszosie reports this Lublin-region round from Suchowola; mapped here as the same round – please confirm.
A24: E23 | B24: 46152 | C24: 46152 | D24: In Flanders Fields | F24: BEL | G24: ROAD | H24: 1.1 | I24: Yes | J24: No | K24: No | L24: =COUNTIF(Results!$A$2:$A$482,A24) -> 0 | M24: =SUMIFS(Results!$M$2:$M$482,Results!$A$2:$A$482,A24) -> 0 | N24: =IF(COUNTIFS(Results!$A$2:$A$482,A24,Results!$G$2:$G$482,">0")=0,"",_xlfn.MINIFS(Results!$G$2:$G$482,Results!$A$2:$A$482,A24,Results!$G$2:$G$482,">0")) | O24: =COUNTIFS(Results!$A$2:$A$482,A24,Results!$G$2:$G$482,1) -> 0 | P24: =IF(K24="Yes","Training",IF(L24>0,"Results found",IF(AND(B24<>"",B24>Summary!$B$4),"Upcoming","No team result found"))) -> No team result found | Q24: Same day as Trofee Maarten Wynants (E24); team results found only for E24.
A25: E24 | B25: 46152 | C25: 46152 | D25: Trofee Maarten Wynants | E25: Houthalen | F25: BEL | G25: ROAD | H25: 1.1 | I25: Yes | J25: No | K25: No | L25: =COUNTIF(Results!$A$2:$A$482,A25) -> 5 | M25: =SUMIFS(Results!$M$2:$M$482,Results!$A$2:$A$482,A25) -> 5 | N25: =IF(COUNTIFS(Results!$A$2:$A$482,A25,Results!$G$2:$G$482,">0")=0,"",_xlfn.MINIFS(Results!$G$2:$G$482,Results!$A$2:$A$482,A25,Results!$G$2:$G$482,">0")) -> 9 | O25: =COUNTIFS(Results!$A$2:$A$482,A25,Results!$G$2:$G$482,1) -> 0 | P25: =IF(K25="Yes","Training",IF(L25>0,"Results found",IF(AND(B25<>"",B25>Summary!$B$4),"Upcoming","No team result found"))) -> Results found
A26: E25 | B26: 46156 | C26: 46159 | D26: Tour de Feminin | E26: Krásná Lípa | F26: CZE | G26: ROAD | H26: 2.2 | I26: Yes | J26: No | K26: No | L26: =COUNTIF(Results!$A$2:$A$482,A26) -> 30 | M26: =SUMIFS(Results!$M$2:$M$482,Results!$A$2:$A$482,A26) -> 6 | N26: =IF(COUNTIFS(Results!$A$2:$A$482,A26,Results!$G$2:$G$482,">0")=0,"",_xlfn.MINIFS(Results!$G$2:$G$482,Results!$A$2:$A$482,A26,Results!$G$2:$G$482,">0")) -> 3 | O26: =COUNTIFS(Results!$A$2:$A$482,A26,Results!$G$2:$G$482,1) -> 0 | P26: =IF(K26="Yes","Training",IF(L26>0,"Results found",IF(AND(B26<>"",B26>Summary!$B$4),"Upcoming","No team result found"))) -> Results found | Q26: Stage 1 was a 12 km team time trial.
A27: E26 | B27: 46164 | C27: 46167 | D27: Sportland Niederösterreich Women Tour | F27: AUT | G27: ROAD | H27: Nat. | I27: Yes | J27: No | K27: No | L27: =COUNTIF(Results!$A$2:$A$482,A27) -> 0 | M27: =SUMIFS(Results!$M$2:$M$482,Results!$A$2:$A$482,A27) -> 0 | N27: =IF(COUNTIFS(Results!$A$2:$A$482,A27,Results!$G$2:$G$482,">0")=0,"",_xlfn.MINIFS(Results!$G$2:$G$482,Results!$A$2:$A$482,A27,Results!$G$2:$G$482,">0")) | O27: =COUNTIFS(Results!$A$2:$A$482,A27,Results!$G$2:$G$482,1) -> 0 | P27: =IF(K27="Yes","Training",IF(L27>0,"Results found",IF(AND(B27<>"",B27>Summary!$B$4),"Upcoming","No team result found"))) -> No team result found
A28: E27 | B28: 46165 | C28: 46166 | D28: Polish Cup (road) – Lubuskie Warte Zachodu | E28: Zielona Góra (Racula / Zabór) | F28: POL | G28: ROAD | H28: Nat. | I28: Yes | J28: No | K28: No | L28: =COUNTIF(Results!$A$2:$A$482,A28) -> 4 | M28: =SUMIFS(Results!$M$2:$M$482,Results!$A$2:$A$482,A28) -> 3 | N28: =IF(COUNTIFS(Results!$A$2:$A$482,A28,Results!$G$2:$G$482,">0")=0,"",_xlfn.MINIFS(Results!$G$2:$G$482,Results!$A$2:$A$482,A28,Results!$G$2:$G$482,">0")) -> 1 | O28: =COUNTIFS(Results!$A$2:$A$482,A28,Results!$G$2:$G$482,1) -> 2 | P28: =IF(K28="Yes","Training",IF(L28>0,"Results found",IF(AND(B28<>"",B28>Summary!$B$4),"Upcoming","No team result found"))) -> Results found
A29: E28 | B29: 46172 | C29: 46173 | D29: Polish Cup (road) | E29: Darłowo (Dąbki / Jarosławiec) | F29: POL | G29: ROAD | H29: Nat. | I29: Yes | J29: No | K29: No | L29: =COUNTIF(Results!$A$2:$A$482,A29) -> 2 | M29: =SUMIFS(Results!$M$2:$M$482,Results!$A$2:$A$482,A29) -> 2 | N29: =IF(COUNTIFS(Results!$A$2:$A$482,A29,Results!$G$2:$G$482,">0")=0,"",_xlfn.MINIFS(Results!$G$2:$G$482,Results!$A$2:$A$482,A29,Results!$G$2:$G$482,">0")) -> 1 | O29: =COUNTIFS(Results!$A$2:$A$482,A29,Results!$G$2:$G$482,1) -> 2 | P29: =IF(K29="Yes","Training",IF(L29>0,"Results found",IF(AND(B29<>"",B29>Summary!$B$4),"Upcoming","No team result found"))) -> Results found
A30: E29 | B30: 46180 | C30: 46180 | D30: Dwars door de Westhoek | F30: BEL | G30: ROAD | H30: 1.1 | I30: Yes | J30: No | K30: No | L30: =COUNTIF(Results!$A$2:$A$482,A30) -> 7 | M30: =SUMIFS(Results!$M$2:$M$482,Results!$A$2:$A$482,A30) -> 7 | N30: =IF(COUNTIFS(Results!$A$2:$A$482,A30,Results!$G$2:$G$482,">0")=0,"",_xlfn.MINIFS(Results!$G$2:$G$482,Results!$A$2:$A$482,A30,Results!$G$2:$G$482,">0")) -> 18 | O30: =COUNTIFS(Results!$A$2:$A$482,A30,Results!$G$2:$G$482,1) -> 0 | P30: =IF(K30="Yes","Training",IF(L30>0,"Results found",IF(AND(B30<>"",B30>Summary!$B$4),"Upcoming","No team result found"))) -> Results found
A31: E30 | B31: 46186 | C31: 46187 | D31: Polish Cup (road) | E31: Koziegłowy / Pińczyce | F31: POL | G31: ROAD | H31: Nat. | I31: Yes | J31: No | K31: No | L31: =COUNTIF(Results!$A$2:$A$482,A31) -> 3 | M31: =SUMIFS(Results!$M$2:$M$482,Results!$A$2:$A$482,A31) -> 2 | N31: =IF(COUNTIFS(Results!$A$2:$A$482,A31,Results!$G$2:$G$482,">0")=0,"",_xlfn.MINIFS(Results!$G$2:$G$482,Results!$A$2:$A$482,A31,Results!$G$2:$G$482,">0")) -> 1 | O31: =COUNTIFS(Results!$A$2:$A$482,A31,Results!$G$2:$G$482,1) -> 2 | P31: =IF(K31="Yes","Training",IF(L31>0,"Results found",IF(AND(B31<>"",B31>Summary!$B$4),"Upcoming","No team result found"))) -> Results found
A32: E31 | B32: 46193 | C32: 46194 | D32: Polish Cup (road) – Memoriał Tomka Jakubowskiego | E32: Chrzypsko Wielkie / Lusowo | F32: POL | G32: ROAD | H32: Nat. | I32: Yes | J32: No | K32: No | L32: =COUNTIF(Results!$A$2:$A$482,A32) -> 0 | M32: =SUMIFS(Results!$M$2:$M$482,Results!$A$2:$A$482,A32) -> 0 | N32: =IF(COUNTIFS(Results!$A$2:$A$482,A32,Results!$G$2:$G$482,">0")=0,"",_xlfn.MINIFS(Results!$G$2:$G$482,Results!$A$2:$A$482,A32,Results!$G$2:$G$482,">0")) | O32: =COUNTIFS(Results!$A$2:$A$482,A32,Results!$G$2:$G$482,1) -> 0 | P32: =IF(K32="Yes","Training",IF(L32>0,"Results found",IF(AND(B32<>"",B32>Summary!$B$4),"Upcoming","No team result found"))) -> No team result found | Q32: No team rider in the places reported by naszosie.
A33: E32 | B33: 46194 | C33: 46194 | D33: LOTTO Thüringen Women Cycling Challenge | F33: GER | G33: ROAD | H33: 1.Pro | I33: Yes | J33: No | K33: No | L33: =COUNTIF(Results!$A$2:$A$482,A33) -> 6 | M33: =SUMIFS(Results!$M$2:$M$482,Results!$A$2:$A$482,A33) -> 6 | N33: =IF(COUNTIFS(Results!$A$2:$A$482,A33,Results!$G$2:$G$482,">0")=0,"",_xlfn.MINIFS(Results!$G$2:$G$482,Results!$A$2:$A$482,A33,Results!$G$2:$G$482,">0")) -> 8 | O33: =COUNTIFS(Results!$A$2:$A$482,A33,Results!$G$2:$G$482,1) -> 0 | P33: =IF(K33="Yes","Training",IF(L33>0,"Results found",IF(AND(B33<>"",B33>Summary!$B$4),"Upcoming","No team result found"))) -> Results found
A34: E33 | B34: 46198 | C34: 46202 | D34: Polish Road Championships (ITT + road race) | F34: POL | G34: ROAD | H34: NCh. | I34: Yes | J34: Yes | K34: No | L34: =COUNTIF(Results!$A$2:$A$482,A34) -> 35 | M34: =SUMIFS(Results!$M$2:$M$482,Results!$A$2:$A$482,A34) -> 18 | N34: =IF(COUNTIFS(Results!$A$2:$A$482,A34,Results!$G$2:$G$482,">0")=0,"",_xlfn.MINIFS(Results!$G$2:$G$482,Results!$A$2:$A$482,A34,Results!$G$2:$G$482,">0")) -> 1 | O34: =COUNTIFS(Results!$A$2:$A$482,A34,Results!$G$2:$G$482,1) -> 2 | P34: =IF(K34="Yes","Training",IF(L34>0,"Results found",IF(AND(B34<>"",B34>Summary!$B$4),"Upcoming","No team result found"))) -> Results found | Q34: ITT 25 Jun, U19 road race 28 Jun, elite/U23 road race 27 Jun.
A35: E34 | B35: 46210 | C35: 46215 | D35: UEC Track Junior & U23 European Championships | E35: Cottbus | F35: GER | G35: TRACK | H35: ECh. | I35: Yes | J35: No | K35: No | L35: =COUNTIF(Results!$A$2:$A$482,A35) -> 16 | M35: =SUMIFS(Results!$M$2:$M$482,Results!$A$2:$A$482,A35) -> 6 | N35: =IF(COUNTIFS(Results!$A$2:$A$482,A35,Results!$G$2:$G$482,">0")=0,"",_xlfn.MINIFS(Results!$G$2:$G$482,Results!$A$2:$A$482,A35,Results!$G$2:$G$482,">0")) -> 3 | O35: =COUNTIFS(Results!$A$2:$A$482,A35,Results!$G$2:$G$482,1) -> 0 | P35: =IF(K35="Yes","Training",IF(L35>0,"Results found",IF(AND(B35<>"",B35>Summary!$B$4),"Upcoming","No team result found"))) -> Results found | Q35: Riders raced for Poland.
A36: E35 | B36: 46214 | C36: 46214 | D36: Respect Ladies Race Slovakia | F36: SVK | G36: ROAD | H36: 1.2 | I36: Yes | J36: No | K36: No | L36: =COUNTIF(Results!$A$2:$A$482,A36) -> 6 | M36: =SUMIFS(Results!$M$2:$M$482,Results!$A$2:$A$482,A36) -> 6 | N36: =IF(COUNTIFS(Results!$A$2:$A$482,A36,Results!$G$2:$G$482,">0")=0,"",_xlfn.MINIFS(Results!$G$2:$G$482,Results!$A$2:$A$482,A36,Results!$G$2:$G$482,">0")) -> 2 | O36: =COUNTIFS(Results!$A$2:$A$482,A36,Results!$G$2:$G$482,1) -> 0 | P36: =IF(K36="Yes","Training",IF(L36>0,"Results found",IF(AND(B36<>"",B36>Summary!$B$4),"Upcoming","No team result found"))) -> Results found | Q36: Listed on the team site as Groupama Ladies Race Slovakia.
A37: E36 | B37: 46227 | C37: 46229 | D37: Tour de Pologne Women | E37: Zamość – Lublin | F37: POL | G37: ROAD | H37: 2.Pro | I37: Yes | J37: No | K37: No | L37: =COUNTIF(Results!$A$2:$A$482,A37) -> 24 | M37: =SUMIFS(Results!$M$2:$M$482,Results!$A$2:$A$482,A37) -> 6 | N37: =IF(COUNTIFS(Results!$A$2:$A$482,A37,Results!$G$2:$G$482,">0")=0,"",_xlfn.MINIFS(Results!$G$2:$G$482,Results!$A$2:$A$482,A37,Results!$G$2:$G$482,">0")) -> 5 | O37: =COUNTIFS(Results!$A$2:$A$482,A37,Results!$G$2:$G$482,1) -> 0 | P37: =IF(K37="Yes","Training",IF(L37>0,"Results found",IF(AND(B37<>"",B37>Summary!$B$4),"Upcoming","No team result found"))) -> Results found
A38: E37 | B38: 46227 | C38: 46229 | D38: Watersley Ladies Challenge | E38: Watersley | F38: NED | G38: ROAD | H38: 2.Ncup | I38: Yes | J38: No | K38: No | L38: =COUNTIF(Results!$A$2:$A$482,A38) -> 21 | M38: =SUMIFS(Results!$M$2:$M$482,Results!$A$2:$A$482,A38) -> 6 | N38: =IF(COUNTIFS(Results!$A$2:$A$482,A38,Results!$G$2:$G$482,">0")=0,"",_xlfn.MINIFS(Results!$G$2:$G$482,Results!$A$2:$A$482,A38,Results!$G$2:$G$482,">0")) -> 8 | O38: =COUNTIFS(Results!$A$2:$A$482,A38,Results!$G$2:$G$482,1) -> 0 | P38: =IF(K38="Yes","Training",IF(L38>0,"Results found",IF(AND(B38<>"",B38>Summary!$B$4),"Upcoming","No team result found"))) -> Results found | Q38: Junior Nations Cup; juniors raced.
A39: E38 | B39: 46234 | C39: 46234 | D39: Criterium Grudziądz (Puchar Prezydenta Grudziądza) | E39: Grudziądz | F39: POL | G39: ROAD | H39: Nat. | I39: Yes | J39: No | K39: No | L39: =COUNTIF(Results!$A$2:$A$482,A39) -> 5 | M39: =SUMIFS(Results!$M$2:$M$482,Results!$A$2:$A$482,A39) -> 5 | N39: =IF(COUNTIFS(Results!$A$2:$A$482,A39,Results!$G$2:$G$482,">0")=0,"",_xlfn.MINIFS(Results!$G$2:$G$482,Results!$A$2:$A$482,A39,Results!$G$2:$G$482,">0")) -> 1 | O39: =COUNTIFS(Results!$A$2:$A$482,A39,Results!$G$2:$G$482,1) -> 1 | P39: =IF(K39="Yes","Training",IF(L39>0,"Results found",IF(AND(B39<>"",B39>Summary!$B$4),"Upcoming","No team result found"))) -> Results found | Q39: naszosie dates the race 8 Aug 2026.
A40: E39 | B40: 46235 | C40: 46235 | D40: Kryterium Uliczne – Nagroda Gruczna | E40: Gruczno | F40: POL | G40: ROAD | H40: Nat. | I40: Yes | J40: No | K40: No | L40: =COUNTIF(Results!$A$2:$A$482,A40) -> 4 | M40: =SUMIFS(Results!$M$2:$M$482,Results!$A$2:$A$482,A40) -> 4 | N40: =IF(COUNTIFS(Results!$A$2:$A$482,A40,Results!$G$2:$G$482,">0")=0,"",_xlfn.MINIFS(Results!$G$2:$G$482,Results!$A$2:$A$482,A40,Results!$G$2:$G$482,">0")) -> 1 | O40: =COUNTIFS(Results!$A$2:$A$482,A40,Results!$G$2:$G$482,1) -> 2 | P40: =IF(K40="Yes","Training",IF(L40>0,"Results found",IF(AND(B40<>"",B40>Summary!$B$4),"Upcoming","No team result found"))) -> Results found | Q40: naszosie report published 9 Aug 2026.
...

Sheet Results
A1: Event ID | B1: Date | C1: Event | D1: Stage / discipline | E1: Category | F1: Rider | G1: Position | H1: Status | I1: Notes | J1: Source | K1: National championship | L1: Checked by team | M1: Rider×event first row | N1: Country | O1: Title (first row) | P1: Medal (first row)
A2: E07 | B2: 46085 | C2: =IF(A2="","",IFERROR(INDEX(Events!$D$2:$D$67,MATCH(A2,Events!$A$2:$A$67,0)),"Unknown event ID")) -> UMAG Classic Ladies | D2: One-day race | E2: Elite | F2: Olga Wankiewicz | G2: 13 | H2: Classified | J2: https://cyclingflash.com/profile/olga-wankiewicz | K2: =IF(A2="","",IFERROR(IF(INDEX(Events!$J$2:$J$67,MATCH(A2,Events!$A$2:$A$67,0))="Yes",IF(ISNUMBER(SEARCH("Criterium final",D2)),"No","Yes"),"No"),"")) -> No | M2: =IF(OR(A2="",F2=""),0,IF(COUNTIFS($A$2:A2,A2,$F$2:F2,F2)=1,1,0)) -> 1 | N2: =IF(A2="","",IFERROR(INDEX(Events!$F$2:$F$67,MATCH(A2,Events!$A$2:$A$67,0)),"")) -> CRO | O2: =IF(AND(G2=1,K2="Yes",N2="POL"),IF(COUNTIFS($A$2:A2,A2,$D$2:D2,D2,$E$2:E2,E2,$G$2:G2,1)=1,1,0),0) -> 0 | P2: =IF(AND(ISNUMBER(G2),K2="Yes",N2="POL"),IF(AND(G2>=1,G2<=3,COUNTIFS($A$2:A2,A2,$D$2:D2,D2,$E$2:E2,E2,$G$2:G2,G2)=1),1,0),0) -> 0
A3: E09 | B3: 46089 | C3: =IF(A3="","",IFERROR(INDEX(Events!$D$2:$D$67,MATCH(A3,Events!$A$2:$A$67,0)),"Unknown event ID")) -> POREČ Classic Ladies | D3: One-day race | E3: Elite | F3: Olga Wankiewicz | G3: 2 | H3: Classified | J3: https://cyclingflash.com/profile/olga-wankiewicz | K3: =IF(A3="","",IFERROR(IF(INDEX(Events!$J$2:$J$67,MATCH(A3,Events!$A$2:$A$67,0))="Yes",IF(ISNUMBER(SEARCH("Criterium final",D3)),"No","Yes"),"No"),"")) -> No | M3: =IF(OR(A3="",F3=""),0,IF(COUNTIFS($A$2:A3,A3,$F$2:F3,F3)=1,1,0)) -> 1 | N3: =IF(A3="","",IFERROR(INDEX(Events!$F$2:$F$67,MATCH(A3,Events!$A$2:$A$67,0)),"")) -> CRO | O3: =IF(AND(G3=1,K3="Yes",N3="POL"),IF(COUNTIFS($A$2:A3,A3,$D$2:D3,D3,$E$2:E3,E3,$G$2:G3,1)=1,1,0),0) -> 0 | P3: =IF(AND(ISNUMBER(G3),K3="Yes",N3="POL"),IF(AND(G3>=1,G3<=3,COUNTIFS($A$2:A3,A3,$D$2:D3,D3,$E$2:E3,E3,$G$2:G3,G3)=1),1,0),0) -> 0
A4: E10 | B4: 46103 | C4: =IF(A4="","",IFERROR(INDEX(Events!$D$2:$D$67,MATCH(A4,Events!$A$2:$A$67,0)),"Unknown event ID")) -> Midwest Cycling Classic | D4: One-day race | E4: Elite | F4: Olga Wankiewicz | G4: 9 | H4: Classified | J4: https://cyclingflash.com/profile/olga-wankiewicz | K4: =IF(A4="","",IFERROR(IF(INDEX(Events!$J$2:$J$67,MATCH(A4,Events!$A$2:$A$67,0))="Yes",IF(ISNUMBER(SEARCH("Criterium final",D4)),"No","Yes"),"No"),"")) -> No | M4: =IF(OR(A4="",F4=""),0,IF(COUNTIFS($A$2:A4,A4,$F$2:F4,F4)=1,1,0)) -> 1 | N4: =IF(A4="","",IFERROR(INDEX(Events!$F$2:$F$67,MATCH(A4,Events!$A$2:$A$67,0)),"")) -> BEL | O4: =IF(AND(G4=1,K4="Yes",N4="POL"),IF(COUNTIFS($A$2:A4,A4,$D$2:D4,D4,$E$2:E4,E4,$G$2:G4,1)=1,1,0),0) -> 0 | P4: =IF(AND(ISNUMBER(G4),K4="Yes",N4="POL"),IF(AND(G4>=1,G4<=3,COUNTIFS($A$2:A4,A4,$D$2:D4,D4,$E$2:E4,E4,$G$2:G4,G4)=1),1,0),0) -> 0
A5: E12 | B5: 46116 | C5: =IF(A5="","",IFERROR(INDEX(Events!$D$2:$D$67,MATCH(A5,Events!$A$2:$A$67,0)),"Unknown event ID")) -> NXT Classic | D5: One-day race | E5: Elite | F5: Olga Wankiewicz | G5: 21 | H5: Classified | J5: https://cyclingflash.com/profile/olga-wankiewicz | K5: =IF(A5="","",IFERROR(IF(INDEX(Events!$J$2:$J$67,MATCH(A5,Events!$A$2:$A$67,0))="Yes",IF(ISNUMBER(SEARCH("Criterium final",D5)),"No","Yes"),"No"),"")) -> No | M5: =IF(OR(A5="",F5=""),0,IF(COUNTIFS($A$2:A5,A5,$F$2:F5,F5)=1,1,0)) -> 1 | N5: =IF(A5="","",IFERROR(INDEX(Events!$F$2:$F$67,MATCH(A5,Events!$A$2:$A$67,0)),"")) -> NED | O5: =IF(AND(G5=1,K5="Yes",N5="POL"),IF(COUNTIFS($A$2:A5,A5,$D$2:D5,D5,$E$2:E5,E5,$G$2:G5,1)=1,1,0),0) -> 0 | P5: =IF(AND(ISNUMBER(G5),K5="Yes",N5="POL"),IF(AND(G5>=1,G5<=3,COUNTIFS($A$2:A5,A5,$D$2:D5,D5,$E$2:E5,E5,$G$2:G5,G5)=1),1,0),0) -> 0
A6: E13 | B6: 46118 | C6: =IF(A6="","",IFERROR(INDEX(Events!$D$2:$D$67,MATCH(A6,Events!$A$2:$A$67,0)),"Unknown event ID")) -> Ronde de Mouscron | D6: One-day race | E6: Elite | F6: Olga Wankiewicz | G6: 7 | H6: Classified | J6: https://cyclingflash.com/profile/olga-wankiewicz | K6: =IF(A6="","",IFERROR(IF(INDEX(Events!$J$2:$J$67,MATCH(A6,Events!$A$2:$A$67,0))="Yes",IF(ISNUMBER(SEARCH("Criterium final",D6)),"No","Yes"),"No"),"")) -> No | M6: =IF(OR(A6="",F6=""),0,IF(COUNTIFS($A$2:A6,A6,$F$2:F6,F6)=1,1,0)) -> 1 | N6: =IF(A6="","",IFERROR(INDEX(Events!$F$2:$F$67,MATCH(A6,Events!$A$2:$A$67,0)),"")) -> BEL | O6: =IF(AND(G6=1,K6="Yes",N6="POL"),IF(COUNTIFS($A$2:A6,A6,$D$2:D6,D6,$E$2:E6,E6,$G$2:G6,1)=1,1,0),0) -> 0 | P6: =IF(AND(ISNUMBER(G6),K6="Yes",N6="POL"),IF(AND(G6>=1,G6<=3,COUNTIFS($A$2:A6,A6,$D$2:D6,D6,$E$2:E6,E6,$G$2:G6,G6)=1),1,0),0) -> 0
A7: E15 | B7: 46124 | C7: =IF(A7="","",IFERROR(INDEX(Events!$D$2:$D$67,MATCH(A7,Events!$A$2:$A$67,0)),"Unknown event ID")) -> Ślężański Mnich | D7: Road race | E7: Elite | F7: Olga Wankiewicz | G7: 3 | H7: Classified | J7: https://naszosie.pl/2026/04/12/slezanski-mnich-2026-mat-atom-deweloper-wroclaw-zgarnia-cale-podium/ | K7: =IF(A7="","",IFERROR(IF(INDEX(Events!$J$2:$J$67,MATCH(A7,Events!$A$2:$A$67,0))="Yes",IF(ISNUMBER(SEARCH("Criterium final",D7)),"No","Yes"),"No"),"")) -> No | M7: =IF(OR(A7="",F7=""),0,IF(COUNTIFS($A$2:A7,A7,$F$2:F7,F7)=1,1,0)) -> 1 | N7: =IF(A7="","",IFERROR(INDEX(Events!$F$2:$F$67,MATCH(A7,Events!$A$2:$A$67,0)),"")) -> POL | O7: =IF(AND(G7=1,K7="Yes",N7="POL"),IF(COUNTIFS($A$2:A7,A7,$D$2:D7,D7,$E$2:E7,E7,$G$2:G7,1)=1,1,0),0) -> 0 | P7: =IF(AND(ISNUMBER(G7),K7="Yes",N7="POL"),IF(AND(G7>=1,G7<=3,COUNTIFS($A$2:A7,A7,$D$2:D7,D7,$E$2:E7,E7,$G$2:G7,G7)=1),1,0),0) -> 0
A8: X02 | B8: 46129 | C8: =IF(A8="","",IFERROR(INDEX(Events!$D$2:$D$67,MATCH(A8,Events!$A$2:$A$67,0)),"Unknown event ID")) -> UCI Track Nations Cup – Hong Kong | D8: Team pursuit | E8: Elite | F8: Olga Wankiewicz | G8: 9 | H8: Classified | J8: https://cyclingflash.com/profile/olga-wankiewicz | K8: =IF(A8="","",IFERROR(IF(INDEX(Events!$J$2:$J$67,MATCH(A8,Events!$A$2:$A$67,0))="Yes",IF(ISNUMBER(SEARCH("Criterium final",D8)),"No","Yes"),"No"),"")) -> No | M8: =IF(OR(A8="",F8=""),0,IF(COUNTIFS($A$2:A8,A8,$F$2:F8,F8)=1,1,0)) -> 1 | N8: =IF(A8="","",IFERROR(INDEX(Events!$F$2:$F$67,MATCH(A8,Events!$A$2:$A$67,0)),"")) -> HKG | O8: =IF(AND(G8=1,K8="Yes",N8="POL"),IF(COUNTIFS($A$2:A8,A8,$D$2:D8,D8,$E$2:E8,E8,$G$2:G8,1)=1,1,0),0) -> 0 | P8: =IF(AND(ISNUMBER(G8),K8="Yes",N8="POL"),IF(AND(G8>=1,G8<=3,COUNTIFS($A$2:A8,A8,$D$2:D8,D8,$E$2:E8,E8,$G$2:G8,G8)=1),1,0),0) -> 0
A9: X02 | B9: 46130 | C9: =IF(A9="","",IFERROR(INDEX(Events!$D$2:$D$67,MATCH(A9,Events!$A$2:$A$67,0)),"Unknown event ID")) -> UCI Track Nations Cup – Hong Kong | D9: Madison | E9: Elite | F9: Olga Wankiewicz | G9: 10 | H9: Classified | J9: https://cyclingflash.com/profile/olga-wankiewicz | K9: =IF(A9="","",IFERROR(IF(INDEX(Events!$J$2:$J$67,MATCH(A9,Events!$A$2:$A$67,0))="Yes",IF(ISNUMBER(SEARCH("Criterium final",D9)),"No","Yes"),"No"),"")) -> No | M9: =IF(OR(A9="",F9=""),0,IF(COUNTIFS($A$2:A9,A9,$F$2:F9,F9)=1,1,0)) -> 0 | N9: =IF(A9="","",IFERROR(INDEX(Events!$F$2:$F$67,MATCH(A9,Events!$A$2:$A$67,0)),"")) -> HKG | O9: =IF(AND(G9=1,K9="Yes",N9="POL"),IF(COUNTIFS($A$2:A9,A9,$D$2:D9,D9,$E$2:E9,E9,$G$2:G9,1)=1,1,0),0) -> 0 | P9: =IF(AND(ISNUMBER(G9),K9="Yes",N9="POL"),IF(AND(G9>=1,G9<=3,COUNTIFS($A$2:A9,A9,$D$2:D9,D9,$E$2:E9,E9,$G$2:G9,G9)=1),1,0),0) -> 0
A10: X02 | B10: 46131 | C10: =IF(A10="","",IFERROR(INDEX(Events!$D$2:$D$67,MATCH(A10,Events!$A$2:$A$67,0)),"Unknown event ID")) -> UCI Track Nations Cup – Hong Kong | D10: Omnium | E10: Elite | F10: Olga Wankiewicz | G10: 13 | H10: Classified | J10: https://cyclingflash.com/profile/olga-wankiewicz | K10: =IF(A10="","",IFERROR(IF(INDEX(Events!$J$2:$J$67,MATCH(A10,Events!$A$2:$A$67,0))="Yes",IF(ISNUMBER(SEARCH("Criterium final",D10)),"No","Yes"),"No"),"")) -> No | M10: =IF(OR(A10="",F10=""),0,IF(COUNTIFS($A$2:A10,A10,$F$2:F10,F10)=1,1,0)) -> 0 | N10: =IF(A10="","",IFERROR(INDEX(Events!$F$2:$F$67,MATCH(A10,Events!$A$2:$A$67,0)),"")) -> HKG | O10: =IF(AND(G10=1,K10="Yes",N10="POL"),IF(COUNTIFS($A$2:A10,A10,$D$2:D10,D10,$E$2:E10,E10,$G$2:G10,1)=1,1,0),0) -> 0 | P10: =IF(AND(ISNUMBER(G10),K10="Yes",N10="POL"),IF(AND(G10>=1,G10<=3,COUNTIFS($A$2:A10,A10,$D$2:D10,D10,$E$2:E10,E10,$G$2:G10,G10)=1),1,0),0) -> 0
A11: X03 | B11: 46136 | C11: =IF(A11="","",IFERROR(INDEX(Events!$D$2:$D$67,MATCH(A11,Events!$A$2:$A$67,0)),"Unknown event ID")) -> UCI Track Nations Cup – Nilai | D11: Team pursuit | E11: Elite | F11: Olga Wankiewicz | G11: 8 | H11: Classified | J11: https://cyclingflash.com/profile/olga-wankiewicz | K11: =IF(A11="","",IFERROR(IF(INDEX(Events!$J$2:$J$67,MATCH(A11,Events!$A$2:$A$67,0))="Yes",IF(ISNUMBER(SEARCH("Criterium final",D11)),"No","Yes"),"No"),"")) -> No | M11: =IF(OR(A11="",F11=""),0,IF(COUNTIFS($A$2:A11,A11,$F$2:F11,F11)=1,1,0)) -> 1 | N11: =IF(A11="","",IFERROR(INDEX(Events!$F$2:$F$67,MATCH(A11,Events!$A$2:$A$67,0)),"")) -> MAS | O11: =IF(AND(G11=1,K11="Yes",N11="POL"),IF(COUNTIFS($A$2:A11,A11,$D$2:D11,D11,$E$2:E11,E11,$G$2:G11,1)=1,1,0),0) -> 0 | P11: =IF(AND(ISNUMBER(G11),K11="Yes",N11="POL"),IF(AND(G11>=1,G11<=3,COUNTIFS($A$2:A11,A11,$D$2:D11,D11,$E$2:E11,E11,$G$2:G11,G11)=1),1,0),0) -> 0
A12: X03 | B12: 46137 | C12: =IF(A12="","",IFERROR(INDEX(Events!$D$2:$D$67,MATCH(A12,Events!$A$2:$A$67,0)),"Unknown event ID")) -> UCI Track Nations Cup – Nilai | D12: Madison | E12: Elite | F12: Olga Wankiewicz | G12: 9 | H12: Classified | J12: https://cyclingflash.com/profile/olga-wankiewicz | K12: =IF(A12="","",IFERROR(IF(INDEX(Events!$J$2:$J$67,MATCH(A12,Events!$A$2:$A$67,0))="Yes",IF(ISNUMBER(SEARCH("Criterium final",D12)),"No","Yes"),"No"),"")) -> No | M12: =IF(OR(A12="",F12=""),0,IF(COUNTIFS($A$2:A12,A12,$F$2:F12,F12)=1,1,0)) -> 0 | N12: =IF(A12="","",IFERROR(INDEX(Events!$F$2:$F$67,MATCH(A12,Events!$A$2:$A$67,0)),"")) -> MAS | O12: =IF(AND(G12=1,K12="Yes",N12="POL"),IF(COUNTIFS($A$2:A12,A12,$D$2:D12,D12,$E$2:E12,E12,$G$2:G12,1)=1,1,0),0) -> 0 | P12: =IF(AND(ISNUMBER(G12),K12="Yes",N12="POL"),IF(AND(G12>=1,G12<=3,COUNTIFS($A$2:A12,A12,$D$2:D12,D12,$E$2:E12,E12,$G$2:G12,G12)=1),1,0),0) -> 0
A13: X03 | B13: 46138 | C13: =IF(A13="","",IFERROR(INDEX(Events!$D$2:$D$67,MATCH(A13,Events!$A$2:$A$67,0)),"Unknown event ID")) -> UCI Track Nations Cup – Nilai | D13: Omnium | E13: Elite | F13: Olga Wankiewicz | G13: 13 | H13: Classified | J13: https://cyclingflash.com/profile/olga-wankiewicz | K13: =IF(A13="","",IFERROR(IF(INDEX(Events!$J$2:$J$67,MATCH(A13,Events!$A$2:$A$67,0))="Yes",IF(ISNUMBER(SEARCH("Criterium final",D13)),"No","Yes"),"No"),"")) -> No | M13: =IF(OR(A13="",F13=""),0,IF(COUNTIFS($A$2:A13,A13,$F$2:F13,F13)=1,1,0)) -> 0 | N13: =IF(A13="","",IFERROR(INDEX(Events!$F$2:$F$67,MATCH(A13,Events!$A$2:$A$67,0)),"")) -> MAS | O13: =IF(AND(G13=1,K13="Yes",N13="POL"),IF(COUNTIFS($A$2:A13,A13,$D$2:D13,D13,$E$2:E13,E13,$G$2:G13,1)=1,1,0),0) -> 0 | P13: =IF(AND(ISNUMBER(G13),K13="Yes",N13="POL"),IF(AND(G13>=1,G13<=3,COUNTIFS($A$2:A13,A13,$D$2:D13,D13,$E$2:E13,E13,$G$2:G13,G13)=1),1,0),0) -> 0
... A26: E36 | B26: 46229 | C26: =IF(A26="","",IFERROR(INDEX(Events!$D$2:$D$67,MATCH(A26,Events!$A$2:$A$67,0)),"Unknown event ID")) -> Tour de Pologne Women | D26: General classification (final) | E26: Elite | F26: Olga Wankiewicz | G26: 9 | H26: Classified | J26: https://cyclingflash.com/profile/olga-wankiewicz | K26: =IF(A26="","",IFERROR(IF(INDEX(Events!$J$2:$J$67,MATCH(A26,Events!$A$2:$A$67,0))="Yes",IF(ISNUMBER(SEARCH("Criterium final",D26)),"No","Yes"),"No"),"")) -> No | M26: =IF(OR(A26="",F26=""),0,IF(COUNTIFS($A$2:A26,A26,$F$2:F26,F26)=1,1,0)) -> 0 | N26: =IF(A26="","",IFERROR(INDEX(Events!$F$2:$F$67,MATCH(A26,Events!$A$2:$A$67,0)),"")) -> POL | O26: =IF(AND(G26=1,K26="Yes",N26="POL"),IF(COUNTIFS($A$2:A26,A26,$D$2:D26,D26,$E$2:E26,E26,$G$2:G26,1)=1,1,0),0) -> 0 | P26: =IF(AND(ISNUMBER(G26),K26="Yes",N26="POL"),IF(AND(G26>=1,G26<=3,COUNTIFS($A$2:A26,A26,$D$2:D26,D26,$E$2:E26,E26,$G$2:G26,G26)=1),1,0),0) -> 0
A27: E40 | B27: 46235 | C27: =IF(A27="","",IFERROR(INDEX(Events!$D$2:$D$67,MATCH(A27,Events!$A$2:$A$67,0)),"Unknown event ID")) -> Polish Elite Track Championships | D27: Team pursuit | E27: Elite | F27: Olga Wankiewicz | G27: 1 | H27: Classified | I27: With Kaczmarczyk, Tracka, Sipko, Szczęsna | J27: https://naszosie.pl/2026/08/02/mistrzostwa-polski-elity-w-kolarstwie-torowym-2026-wyniki-z-1-dnia/ | K27: =IF(A27="","",IFERROR(IF(INDEX(Events!$J$2:$J$67,MATCH(A27,Events!$A$2:$A$67,0))="Yes",IF(ISNUMBER(SEARCH("Criterium final",D27)),"No","Yes"),"No"),"")) -> Yes | M27: =IF(OR(A27="",F27=""),0,IF(COUNTIFS($A$2:A27,A27,$F$2:F27,F27)=1,1,0)) -> 1 | N27: =IF(A27="","",IFERROR(INDEX(Events!$F$2:$F$67,MATCH(A27,Events!$A$2:$A$67,0)),"")) -> POL | O27: =IF(AND(G27=1,K27="Yes",N27="POL"),IF(COUNTIFS($A$2:A27,A27,$D$2:D27,D27,$E$2:E27,E27,$G$2:G27,1)=1,1,0),0) -> 1 | P27: =IF(AND(ISNUMBER(G27),K27="Yes",N27="POL"),IF(AND(G27>=1,G27<=3,COUNTIFS($A$2:A27,A27,$D$2:D27,D27,$E$2:E27,E27,$G$2:G27,G27)=1),1,0),0) -> 1
A28: E40 | B28: 46236 | C28: =IF(A28="","",IFERROR(INDEX(Events!$D$2:$D$67,MATCH(A28,Events!$A$2:$A$67,0)),"Unknown event ID")) -> Polish Elite Track Championships | D28: Elimination race | E28: Elite | F28: Olga Wankiewicz | G28: 3 | H28: Classified | J28: https://naszosie.pl/2026/08/02/mistrzostwa-polski-elity-w-kolarstwie-torowym-wyniki-z-2-dnia/ | K28: =IF(A28="","",IFERROR(IF(INDEX(Events!$J$2:$J$67,MATCH(A28,Events!$A$2:$A$67,0))="Yes",IF(ISNUMBER(SEARCH("Criterium final",D28)),"No","Yes"),"No"),"")) -> Yes | M28: =IF(OR(A28="",F28=""),0,IF(COUNTIFS($A$2:A28,A28,$F$2:F28,F28)=1,1,0)) -> 0 | N28: =IF(A28="","",IFERROR(INDEX(Events!$F$2:$F$67,MATCH(A28,Events!$A$2:$A$67,0)),"")) -> POL | O28: =IF(AND(G28=1,K28="Yes",N28="POL"),IF(COUNTIFS($A$2:A28,A28,$D$2:D28,D28,$E$2:E28,E28,$G$2:G28,1)=1,1,0),0) -> 0 | P28: =IF(AND(ISNUMBER(G28),K28="Yes",N28="POL"),IF(AND(G28>=1,G28<=3,COUNTIFS($A$2:A28,A28,$D$2:D28,D28,$E$2:E28,E28,$G$2:G28,G28)=1),1,0),0) -> 1
A29: E40 | B29: 46237 | C29: =IF(A29="","",IFERROR(INDEX(Events!$D$2:$D$67,MATCH(A29,Events!$A$2:$A$67,0)),"Unknown event ID")) -> Polish Elite Track Championships | D29: Madison | E29: Elite | F29: Olga Wankiewicz | G29: 2 | H29: Classified | I29: With Szczęsna | J29: https://naszosie.pl/2026/08/03/mistrzostwa-polski-elity-w-kolarstwie-torowym-2026-wyniki-z-3-dnia/ | K29: =IF(A29="","",IFERROR(IF(INDEX(Events!$J$2:$J$67,MATCH(A29,Events!$A$2:$A$67,0))="Yes",IF(ISNUMBER(SEARCH("Criterium final",D29)),"No","Yes"),"No"),"")) -> Yes | M29: =IF(OR(A29="",F29=""),0,IF(COUNTIFS($A$2:A29,A29,$F$2:F29,F29)=1,1,0)) -> 0 | N29: =IF(A29="","",IFERROR(INDEX(Events!$F$2:$F$67,MATCH(A29,Events!$A$2:$A$67,0)),"")) -> POL | O29: =IF(AND(G29=1,K29="Yes",N29="POL"),IF(COUNTIFS($A$2:A29,A29,$D$2:D29,D29,$E$2:E29,E29,$G$2:G29,1)=1,1,0),0) -> 0 | P29: =IF(AND(ISNUMBER(G29),K29="Yes",N29="POL"),IF(AND(G29>=1,G29<=3,COUNTIFS($A$2:A29,A29,$D$2:D29,D29,$E$2:E29,E29,$G$2:G29,G29)=1),1,0),0) -> 1
A30: X11 | B30: 46254 | C30: =IF(A30="","",IFERROR(INDEX(Events!$D$2:$D$67,MATCH(A30,Events!$A$2:$A$67,0)),"Unknown event ID")) -> GP Lucien Van Impe | D30: One-day race | E30: Elite | F30: Olga Wankiewicz | G30: 14 | H30: Classified | J30: https://cyclingflash.com/profile/olga-wankiewicz | K30: =IF(A30="","",IFERROR(IF(INDEX(Events!$J$2:$J$67,MATCH(A30,Events!$A$2:$A$67,0))="Yes",IF(ISNUMBER(SEARCH("Criterium final",D30)),"No","Yes"),"No"),"")) -> No | M30: =IF(OR(A30="",F30=""),0,IF(COUNTIFS($A$2:A30,A30,$F$2:F30,F30)=1,1,0)) -> 1 | N30: =IF(A30="","",IFERROR(INDEX(Events!$F$2:$F$67,MATCH(A30,Events!$A$2:$A$67,0)),"")) -> BEL | O30: =IF(AND(G30=1,K30="Yes",N30="POL"),IF(COUNTIFS($A$2:A30,A30,$D$2:D30,D30,$E$2:E30,E30,$G$2:G30,1)=1,1,0),0) -> 0 | P30: =IF(AND(ISNUMBER(G30),K30="Yes",N30="POL"),IF(AND(G30>=1,G30<=3,COUNTIFS($A$2:A30,A30,$D$2:D30,D30,$E$2:E30,E30,$G$2:G30,G30)=1),1,0),0) -> 0
A31: X12 | B31: 46255 | C31: =IF(A31="","",IFERROR(INDEX(Events!$D$2:$D$67,MATCH(A31,Events!$A$2:$A$67,0)),"Unknown event ID")) -> Konvert Kortrijk Koerse | D31: One-day race | E31: Elite | F31: Olga Wankiewicz | G31: 9 | H31: Classified | J31: https://cyclingflash.com/profile/olga-wankiewicz | K31: =IF(A31="","",IFERROR(IF(INDEX(Events!$J$2:$J$67,MATCH(A31,Events!$A$2:$A$67,0))="Yes",IF(ISNUMBER(SEARCH("Criterium final",D31)),"No","Yes"),"No"),"")) -> No | M31: =IF(OR(A31="",F31=""),0,IF(COUNTIFS($A$2:A31,A31,$F$2:F31,F31)=1,1,0)) -> 1 | N31: =IF(A31="","",IFERROR(INDEX(Events!$F$2:$F$67,MATCH(A31,Events!$A$2:$A$67,0)),"")) -> BEL | O31: =IF(AND(G31=1,K31="Yes",N31="POL"),IF(COUNTIFS($A$2:A31,A31,$D$2:D31,D31,$E$2:E31,E31,$G$2:G31,1)=1,1,0),0) -> 0 | P31: =IF(AND(ISNUMBER(G31),K31="Yes",N31="POL"),IF(AND(G31>=1,G31<=3,COUNTIFS($A$2:A31,A31,$D$2:D31,D31,$E$2:E31,E31,$G$2:G31,G31)=1),1,0),0) -> 0
A32: E03 | B32: 46055 | C32: =IF(A32="","",IFERROR(INDEX(Events!$D$2:$D$67,MATCH(A32,Events!$A$2:$A$67,0)),"Unknown event ID")) -> UEC Track Elite European Championships | D32: Team pursuit | E32: Elite | F32: Tamara Szalińska | G32: 9 | H32: Classified | J32: https://cyclingflash.com/profile/tamara-szalinska | K32: =IF(A32="","",IFERROR(IF(INDEX(Events!$J$2:$J$67,MATCH(A32,Events!$A$2:$A$67,0))="Yes",IF(ISNUMBER(SEARCH("Criterium final",D32)),"No","Yes"),"No"),"")) -> No | M32: =IF(OR(A32="",F32=""),0,IF(COUNTIFS($A$2:A32,A32,$F$2:F32,F32)=1,1,0)) -> 1 | N32: =IF(A32="","",IFERROR(INDEX(Events!$F$2:$F$67,MATCH(A32,Events!$A$2:$A$67,0)),"")) -> TUR | O32: =IF(AND(G32=1,K32="Yes",N32="POL"),IF(COUNTIFS($A$2:A32,A32,$D$2:D32,D32,$E$2:E32,E32,$G$2:G32,1)=1,1,0),0) -> 0 | P32: =IF(AND(ISNUMBER(G32),K32="Yes",N32="POL"),IF(AND(G32>=1,G32<=3,COUNTIFS($A$2:A32,A32,$D$2:D32,D32,$E$2:E32,E32,$G$2:G32,G32)=1),1,0),0) -> 0
A33: E03 | B33: 46057 | C33: =IF(A33="","",IFERROR(INDEX(Events!$D$2:$D$67,MATCH(A33,Events!$A$2:$A$67,0)),"Unknown event ID")) -> UEC Track Elite European Championships | D33: Individual pursuit | E33: Elite | F33: Tamara Szalińska | G33: 17 | H33: Classified | J33: https://cyclingflash.com/profile/tamara-szalinska | K33: =IF(A33="","",IFERROR(IF(INDEX(Events!$J$2:$J$67,MATCH(A33,Events!$A$2:$A$67,0))="Yes",IF(ISNUMBER(SEARCH("Criterium final",D33)),"No","Yes"),"No"),"")) -> No | M33: =IF(OR(A33="",F33=""),0,IF(COUNTIFS($A$2:A33,A33,$F$2:F33,F33)=1,1,0)) -> 0 | N33: =IF(A33="","",IFERROR(INDEX(Events!$F$2:$F$67,MATCH(A33,Events!$A$2:$A$67,0)),"")) -> TUR | O33: =IF(AND(G33=1,K33="Yes",N33="POL"),IF(COUNTIFS($A$2:A33,A33,$D$2:D33,D33,$E$2:E33,E33,$G$2:G33,1)=1,1,0),0) -> 0 | P33: =IF(AND(ISNUMBER(G33),K33="Yes",N33="POL"),IF(AND(G33>=1,G33<=3,COUNTIFS($A$2:A33,A33,$D$2:D33,D33,$E$2:E33,E33,$G$2:G33,G33)=1),1,0),0) -> 0
A34: E07 | B34: 46085 | C34: =IF(A34="","",IFERROR(INDEX(Events!$D$2:$D$67,MATCH(A34,Events!$A$2:$A$67,0)),"Unknown event ID")) -> UMAG Classic Ladies | D34: One-day race | E34: Elite | F34: Tamara Szalińska | G34: 67 | H34: Classified | J34: https://cyclingflash.com/profile/tamara-szalinska | K34: =IF(A34="","",IFERROR(IF(INDEX(Events!$J$2:$J$67,MATCH(A34,Events!$A$2:$A$67,0))="Yes",IF(ISNUMBER(SEARCH("Criterium final",D34)),"No","Yes"),"No"),"")) -> No | M34: =IF(OR(A34="",F34=""),0,IF(COUNTIFS($A$2:A34,A34,$F$2:F34,F34)=1,1,0)) -> 1 | N34: =IF(A34="","",IFERROR(INDEX(Events!$F$2:$F$67,MATCH(A34,Events!$A$2:$A$67,0)),"")) -> CRO | O34: =IF(AND(G34=1,K34="Yes",N34="POL"),IF(COUNTIFS($A$2:A34,A34,$D$2:D34,D34,$E$2:E34,E34,$G$2:G34,1)=1,1,0),0) -> 0 | P34: =IF(AND(ISNUMBER(G34),K34="Yes",N34="POL"),IF(AND(G34>=1,G34<=3,COUNTIFS($A$2:A34,A34,$D$2:D34,D34,$E$2:E34,E34,$G$2:G34,G34)=1),1,0),0) -> 0
A35: E13 | B35: 46118 | C35: =IF(A35="","",IFERROR(INDEX(Events!$D$2:$D$67,MATCH(A35,Events!$A$2:$A$67,0)),"Unknown event ID")) -> Ronde de Mouscron | D35: One-day race | E35: Elite | F35: Tamara Szalińska | G35: 83 | H35: Classified | J35: https://cyclingflash.com/profile/tamara-szalinska | K35: =IF(A35="","",IFERROR(IF(INDEX(Events!$J$2:$J$67,MATCH(A35,Events!$A$2:$A$67,0))="Yes",IF(ISNUMBER(SEARCH("Criterium final",D35)),"No","Yes"),"No"),"")) -> No | M35: =IF(OR(A35="",F35=""),0,IF(COUNTIFS($A$2:A35,A35,$F$2:F35,F35)=1,1,0)) -> 1 | N35: =IF(A35="","",IFERROR(INDEX(Events!$F$2:$F$67,MATCH(A35,Events!$A$2:$A$67,0)),"")) -> BEL | O35: =IF(AND(G35=1,K35="Yes",N35="POL"),IF(COUNTIFS($A$2:A35,A35,$D$2:D35,D35,$E$2:E35,E35,$G$2:G35,1)=1,1,0),0) -> 0 | P35: =IF(AND(ISNUMBER(G35),K35="Yes",N35="POL"),IF(AND(G35>=1,G35<=3,COUNTIFS($A$2:A35,A35,$D$2:D35,D35,$E$2:E35,E35,$G$2:G35,G35)=1),1,0),0) -> 0
A36: E14 | B36: 46120 | C36: =IF(A36="","",IFERROR(INDEX(Events!$D$2:$D$67,MATCH(A36,Events!$A$2:$A$67,0)),"Unknown event ID")) -> Scheldeprijs Vrouwen Elite | D36: One-day race | E36: Elite | F36: Tamara Szalińska | G36: 61 | H36: Classified | J36: https://cyclingflash.com/profile/tamara-szalinska | K36: =IF(A36="","",IFERROR(IF(INDEX(Events!$J$2:$J$67,MATCH(A36,Events!$A$2:$A$67,0))="Yes",IF(ISNUMBER(SEARCH("Criterium final",D36)),"No","Yes"),"No"),"")) -> No | M36: =IF(OR(A36="",F36=""),0,IF(COUNTIFS($A$2:A36,A36,$F$2:F36,F36)=1,1,0)) -> 1 | N36: =IF(A36="","",IFERROR(INDEX(Events!$F$2:$F$67,MATCH(A36,Events!$A$2:$A$67,0)),"")) -> BEL | O36: =IF(AND(G36=1,K36="Yes",N36="POL"),IF(COUNTIFS($A$2:A36,A36,$D$2:D36,D36,$E$2:E36,E36,$G$2:G36,1)=1,1,0),0) -> 0 | P36: =IF(AND(ISNUMBER(G36),K36="Yes",N36="POL"),IF(AND(G36>=1,G36<=3,COUNTIFS($A$2:A36,A36,$D$2:D36,D36,$E$2:E36,E36,$G$2:G36,G36)=1),1,0),0) -> 0
